Traceback (most recent call last):
  File "C:\Users\DELL\anaconda3\envs\jupyterbook\Lib\site-packages\jupyter_cache\executors\utils.py", line 58, in single_nb_execution
    executenb(
    ~~~~~~~~~^
        nb,
        ^^^
    ...<4 lines>...
        **kwargs,
        ^^^^^^^^^
    )
    ^
  File "C:\Users\DELL\anaconda3\envs\jupyterbook\Lib\site-packages\nbclient\client.py", line 1314, in execute
    return NotebookClient(nb=nb, resources=resources, km=km, **kwargs).execute()
           ~~~~~~~~~~~~~~~~~~~~~~~~~~~~~~~~~~~~~~~~~~~~~~~~~~~~~~~~~~~~~~~~~~~^^
  File "C:\Users\DELL\anaconda3\envs\jupyterbook\Lib\site-packages\jupyter_core\utils\__init__.py", line 165, in wrapped
    return loop.run_until_complete(inner)
           ~~~~~~~~~~~~~~~~~~~~~~~^^^^^^^
  File "C:\Users\DELL\anaconda3\envs\jupyterbook\Lib\asyncio\base_events.py", line 721, in run_until_complete
    return future.result()
           ~~~~~~~~~~~~~^^
  File "C:\Users\DELL\anaconda3\envs\jupyterbook\Lib\site-packages\nbclient\client.py", line 709, in async_execute
    await self.async_execute_cell(
        cell, index, execution_count=self.code_cells_executed + 1
    )
  File "C:\Users\DELL\anaconda3\envs\jupyterbook\Lib\site-packages\nbclient\client.py", line 1062, in async_execute_cell
    await self._check_raise_for_error(cell, cell_index, exec_reply)
  File "C:\Users\DELL\anaconda3\envs\jupyterbook\Lib\site-packages\nbclient\client.py", line 918, in _check_raise_for_error
    raise CellExecutionError.from_cell_and_msg(cell, exec_reply_content)
nbclient.exceptions.CellExecutionError: An error occurred while executing the following cell:
------------------
class teste_2:
    def __init__():
        print("Esse Ã© o construtor")

objeto_2 = teste_2()
print("deu certo")

------------------


[1;31m---------------------------------------------------------------------------[0m
[1;31mTypeError[0m                                 Traceback (most recent call last)
Cell [1;32mIn[8], line 5[0m
[0;32m      2[0m     [38;5;28;01mdef[39;00m [38;5;21m__init__[39m():
[0;32m      3[0m         [38;5;28mprint[39m([38;5;124m"[39m[38;5;124mEsse Ã© o construtor[39m[38;5;124m"[39m)
[1;32m----> 5[0m objeto_2 [38;5;241m=[39m [43mteste_2[49m[43m([49m[43m)[49m
[0;32m      6[0m [38;5;28mprint[39m([38;5;124m"[39m[38;5;124mdeu certo[39m[38;5;124m"[39m)

[1;31mTypeError[0m: teste_2.__init__() takes 0 positional arguments but 1 was given

