Traceback (most recent call last):
  File "C:\Users\DELL\anaconda3\envs\jupyterbook\Lib\site-packages\jupyter_cache\executors\utils.py", line 58, in single_nb_execution
    executenb(
    ~~~~~~~~~^
        nb,
        ^^^
    ...<4 lines>...
        **kwargs,
        ^^^^^^^^^
    )
    ^
  File "C:\Users\DELL\anaconda3\envs\jupyterbook\Lib\site-packages\nbclient\client.py", line 1314, in execute
    return NotebookClient(nb=nb, resources=resources, km=km, **kwargs).execute()
           ~~~~~~~~~~~~~~~~~~~~~~~~~~~~~~~~~~~~~~~~~~~~~~~~~~~~~~~~~~~~~~~~~~~^^
  File "C:\Users\DELL\anaconda3\envs\jupyterbook\Lib\site-packages\jupyter_core\utils\__init__.py", line 165, in wrapped
    return loop.run_until_complete(inner)
           ~~~~~~~~~~~~~~~~~~~~~~~^^^^^^^
  File "C:\Users\DELL\anaconda3\envs\jupyterbook\Lib\asyncio\base_events.py", line 721, in run_until_complete
    return future.result()
           ~~~~~~~~~~~~~^^
  File "C:\Users\DELL\anaconda3\envs\jupyterbook\Lib\site-packages\nbclient\client.py", line 709, in async_execute
    await self.async_execute_cell(
        cell, index, execution_count=self.code_cells_executed + 1
    )
  File "C:\Users\DELL\anaconda3\envs\jupyterbook\Lib\site-packages\nbclient\client.py", line 1062, in async_execute_cell
    await self._check_raise_for_error(cell, cell_index, exec_reply)
  File "C:\Users\DELL\anaconda3\envs\jupyterbook\Lib\site-packages\nbclient\client.py", line 918, in _check_raise_for_error
    raise CellExecutionError.from_cell_and_msg(cell, exec_reply_content)
nbclient.exceptions.CellExecutionError: An error occurred while executing the following cell:
------------------
import sys

while True:
    print('Digite sair para sair.')
    resposta = input()
    if resposta == 'sair':
        sys.exit()
    print('Voce digitou ' + resposta + '.')
------------------

----- stdout -----
Digite sair para sair.
------------------

[1;31m---------------------------------------------------------------------------[0m
[1;31mStdinNotImplementedError[0m                  Traceback (most recent call last)
Cell [1;32mIn[2], line 5[0m
[0;32m      3[0m [38;5;28;01mwhile[39;00m [38;5;28;01mTrue[39;00m:
[0;32m      4[0m     [38;5;28mprint[39m([38;5;124m'[39m[38;5;124mDigite sair para sair.[39m[38;5;124m'[39m)
[1;32m----> 5[0m     resposta [38;5;241m=[39m [38;5;28;43minput[39;49m[43m([49m[43m)[49m
[0;32m      6[0m     [38;5;28;01mif[39;00m resposta [38;5;241m==[39m [38;5;124m'[39m[38;5;124msair[39m[38;5;124m'[39m:
[0;32m      7[0m         sys[38;5;241m.[39mexit()

File [1;32m~\anaconda3\envs\jupyterbook\Lib\site-packages\ipykernel\kernelbase.py:1281[0m, in [0;36mKernel.raw_input[1;34m(self, prompt)[0m
[0;32m   1279[0m [38;5;28;01mif[39;00m [38;5;129;01mnot[39;00m [38;5;28mself[39m[38;5;241m.[39m_allow_stdin:
[0;32m   1280[0m     msg [38;5;241m=[39m [38;5;124m"[39m[38;5;124mraw_input was called, but this frontend does not support input requests.[39m[38;5;124m"[39m
[1;32m-> 1281[0m     [38;5;28;01mraise[39;00m StdinNotImplementedError(msg)
[0;32m   1282[0m [38;5;28;01mreturn[39;00m [38;5;28mself[39m[38;5;241m.[39m_input_request(
[0;32m   1283[0m     [38;5;28mstr[39m(prompt),
[0;32m   1284[0m     [38;5;28mself[39m[38;5;241m.[39m_parent_ident[[38;5;124m"[39m[38;5;124mshell[39m[38;5;124m"[39m],
[0;32m   1285[0m     [38;5;28mself[39m[38;5;241m.[39mget_parent([38;5;124m"[39m[38;5;124mshell[39m[38;5;124m"[39m),
[0;32m   1286[0m     password[38;5;241m=[39m[38;5;28;01mFalse[39;00m,
[0;32m   1287[0m )

[1;31mStdinNotImplementedError[0m: raw_input was called, but this frontend does not support input requests.

