Traceback (most recent call last):
  File "C:\Users\DELL\anaconda3\envs\jupyterbook\Lib\site-packages\jupyter_cache\executors\utils.py", line 58, in single_nb_execution
    executenb(
    ~~~~~~~~~^
        nb,
        ^^^
    ...<4 lines>...
        **kwargs,
        ^^^^^^^^^
    )
    ^
  File "C:\Users\DELL\anaconda3\envs\jupyterbook\Lib\site-packages\nbclient\client.py", line 1314, in execute
    return NotebookClient(nb=nb, resources=resources, km=km, **kwargs).execute()
           ~~~~~~~~~~~~~~~~~~~~~~~~~~~~~~~~~~~~~~~~~~~~~~~~~~~~~~~~~~~~~~~~~~~^^
  File "C:\Users\DELL\anaconda3\envs\jupyterbook\Lib\site-packages\jupyter_core\utils\__init__.py", line 165, in wrapped
    return loop.run_until_complete(inner)
           ~~~~~~~~~~~~~~~~~~~~~~~^^^^^^^
  File "C:\Users\DELL\anaconda3\envs\jupyterbook\Lib\asyncio\base_events.py", line 721, in run_until_complete
    return future.result()
           ~~~~~~~~~~~~~^^
  File "C:\Users\DELL\anaconda3\envs\jupyterbook\Lib\site-packages\nbclient\client.py", line 709, in async_execute
    await self.async_execute_cell(
        cell, index, execution_count=self.code_cells_executed + 1
    )
  File "C:\Users\DELL\anaconda3\envs\jupyterbook\Lib\site-packages\nbclient\client.py", line 1062, in async_execute_cell
    await self._check_raise_for_error(cell, cell_index, exec_reply)
  File "C:\Users\DELL\anaconda3\envs\jupyterbook\Lib\site-packages\nbclient\client.py", line 918, in _check_raise_for_error
    raise CellExecutionError.from_cell_and_msg(cell, exec_reply_content)
nbclient.exceptions.CellExecutionError: An error occurred while executing the following cell:
------------------
bacon = 42
bacon.insert(1, 'world')
------------------


[1;31m---------------------------------------------------------------------------[0m
[1;31mAttributeError[0m                            Traceback (most recent call last)
Cell [1;32mIn[7], line 2[0m
[0;32m      1[0m bacon [38;5;241m=[39m [38;5;241m42[39m
[1;32m----> 2[0m [43mbacon[49m[38;5;241;43m.[39;49m[43minsert[49m([38;5;241m1[39m, [38;5;124m'[39m[38;5;124mworld[39m[38;5;124m'[39m)

[1;31mAttributeError[0m: 'int' object has no attribute 'insert'

